<?xml version="1.0" encoding="UTF-8"?>
<testng-results total="1" passed="0" failed="1" skipped="0">
  <reporter-output>
  </reporter-output>
  <suite started-at="2020-11-24T19:59:18Z" name="Default suite" finished-at="2020-11-24T20:00:01Z" duration-ms="42814">
    <groups>
    </groups>
    <test started-at="2020-11-24T19:59:18Z" name="Default test" finished-at="2020-11-24T20:00:01Z" duration-ms="42814">
      <class name="newProjectPractice.ExcelDataProvider">
        <test-method signature="LoginTest(java.lang.String, java.lang.String)[pri:0, instance:newProjectPractice.ExcelDataProvider@5a45133e]" started-at="2020-11-25T01:29:19Z" name="LoginTest" data-provider="Test1" finished-at="2020-11-25T01:30:00Z" duration-ms="41014" status="FAIL">
          <params>
            <param index="0">
              <value>
                <![CDATA[muzaffarKhan]]>
              </value>
            </param>
            <param index="1">
              <value>
                <![CDATA[Mka121]]>
              </value>
            </param>
          </params>
          <exception class="java.lang.AssertionError">
            <message>
              <![CDATA[The user name or Password is incorrect expected [true] but found [false]]]>
            </message>
            <full-stacktrace>
              <![CDATA[java.lang.AssertionError: The user name or Password is incorrect expected [true] but found [false]
	at org.testng.Assert.fail(Assert.java:94)
	at org.testng.Assert.failNotEquals(Assert.java:494)
	at org.testng.Assert.assertTrue(Assert.java:42)
	at newProjectPractice.ExcelDataProvider.LoginTest(ExcelDataProvider.java:57)
	at java.base/jdk.internal.reflect.NativeMethodAccessorImpl.invoke0(Native Method)
	at java.base/jdk.internal.reflect.NativeMethodAccessorImpl.invoke(NativeMethodAccessorImpl.java:62)
	at java.base/jdk.internal.reflect.DelegatingMethodAccessorImpl.invoke(DelegatingMethodAccessorImpl.java:43)
	at java.base/java.lang.reflect.Method.invoke(Method.java:564)
	at org.testng.internal.MethodInvocationHelper.invokeMethod(MethodInvocationHelper.java:80)
	at org.testng.internal.Invoker.invokeMethod(Invoker.java:714)
	at org.testng.internal.Invoker.invokeTestMethod(Invoker.java:901)
	at org.testng.internal.Invoker.invokeTestMethods(Invoker.java:1231)
	at org.testng.internal.TestMethodWorker.invokeTestMethods(TestMethodWorker.java:127)
	at org.testng.internal.TestMethodWorker.run(TestMethodWorker.java:111)
	at org.testng.TestRunner.privateRun(TestRunner.java:767)
	at org.testng.TestRunner.run(TestRunner.java:617)
	at org.testng.SuiteRunner.runTest(SuiteRunner.java:334)
	at org.testng.SuiteRunner.runSequentially(SuiteRunner.java:329)
	at org.testng.SuiteRunner.privateRun(SuiteRunner.java:291)
	at org.testng.SuiteRunner.run(SuiteRunner.java:240)
	at org.testng.SuiteRunnerWorker.runSuite(SuiteRunnerWorker.java:52)
	at org.testng.SuiteRunnerWorker.run(SuiteRunnerWorker.java:86)
	at org.testng.TestNG.runSuitesSequentially(TestNG.java:1198)
	at org.testng.TestNG.runSuitesLocally(TestNG.java:1123)
	at org.testng.TestNG.run(TestNG.java:1031)
	at org.testng.remote.AbstractRemoteTestNG.run(AbstractRemoteTestNG.java:115)
	at org.testng.remote.RemoteTestNG.initAndRun(RemoteTestNG.java:251)
	at org.testng.remote.RemoteTestNG.main(RemoteTestNG.java:77)
]]>
            </full-stacktrace>
          </exception> <!-- java.lang.AssertionError -->
          <reporter-output>
          </reporter-output>
        </test-method> <!-- LoginTest -->
        <test-method is-config="true" signature="tearDown()[pri:0, instance:newProjectPractice.ExcelDataProvider@5a45133e]" started-at="2020-11-25T01:30:00Z" name="tearDown" finished-at="2020-11-25T01:30:01Z" duration-ms="925" status="PASS">
          <reporter-output>
          </reporter-output>
        </test-method> <!-- tearDown -->
      </class> <!-- newProjectPractice.ExcelDataProvider -->
    </test> <!-- Default test -->
  </suite> <!-- Default suite -->
</testng-results>
